<?xml version="1.0" ?>
<!-- =================================================================================== -->
<!-- |    This document was autogenerated by xacro from /home/gavin/wangjw/realman75/src/rm_75_description/urdf/dual_arm_robot.urdf.xacro | -->
<!-- |    EDITING THIS FILE BY HAND IS NOT RECOMMENDED                                 | -->
<!-- =================================================================================== -->
<robot name="dual_arm_robot">
    <link name="world" />
    <joint name="world_fixed" type="fixed">
        <origin rpy="0 0 0" xyz="0 0 0" />
        <parent link="world" />
        <child link="dummy" />
    </joint>
    <link name="dummy" />
    <joint name="left_dummy_joint" type="fixed">
        <origin rpy="0 0 0" xyz="0 0.3 0" />
        <parent link="dummy" />
        <child link="left_base_link" />
    </joint>
    <!-- ///////////////////////////////////////   bottom_joint   ////////////////////////////////////////// -->
    <joint name="left_bottom_joint" type="fixed">
        <origin rpy="0 0 0" xyz="0 0 0" />
        <parent link="left_base_link" />
        <child link="left_bottom_link" />
    </joint>
    <link name="left_bottom_link">
        <visual>
            <origin rpy="0 0 0" xyz=" 0 0 -0.02" />
            <geometry>
                <box size="0.06 0.06 0.02" />
            </geometry>
            <material name="Brown" />
        </visual>
        <collision>
            <origin rpy="0 0 0" xyz=" 0 0 -0.02" />
            <geometry>
                <box size="0.06 0.06 0.02" />
            </geometry>
        </collision>
        <inertial>
            <mass value="500" />
            <inertia ixx="41.68333333333333" ixy="0" ixz="0" iyy="83.33333333333333" iyz="0" izz="41.68333333333333" />
            <origin xyz="0 0 0" rpy="0 0 0" />
        </inertial>
    </link>
    <link name="left_base_link">
        <inertial>
            <origin rpy="0 0 0" xyz="0.000433268851866144 3.54527840972405E-05 0.0599427623574736" />
            <mass value="0.841071174772543" />
            <inertia ixx="0.00172611149818605" ixy="2.52724703312125E-06" ixz="3.67689528877993E-05" iyy="0.00170987425756066" iyz="-1.68009023667311E-06" izz="0.000904023916742301" />
        </inertial>
        <visual>
            <origin rpy="0 0 0" xyz="0 0 0" />
            <geometry>
                <mesh filename="package://rm_75_description/meshes/base_link.STL" />
            </geometry>
            <material name="">
                <color rgba="1 1 1 1" />
            </material>
        </visual>
        <collision>
            <origin rpy="0 0 0" xyz="0 0 0" />
            <geometry>
                <mesh filename="package://rm_75_description/meshes/base_link.STL" />
            </geometry>
        </collision>
    </link>
    <link name="left_Link1">
        <inertial>
            <origin rpy="0 0 0" xyz="0.0251854224372461 1.19160585601655E-08 -0.021107996993288" />
            <mass value="0.593563458735581" />
            <inertia ixx="0.000561352422092522" ixy="9.8019294192418E-09" ixz="-0.000211217278563478" iyy="0.00126614121202124" iyz="1.29510293158304E-08" izz="0.0011816817861243" />
        </inertial>
        <visual>
            <origin rpy="0 0 0" xyz="0 0 0" />
            <geometry>
                <mesh filename="package://rm_75_description/meshes/link1.STL" />
            </geometry>
            <material name="">
                <color rgba="1 1 1 1" />
            </material>
        </visual>
        <collision>
            <origin rpy="0 0 0" xyz="0 0 0" />
            <geometry>
                <mesh filename="package://rm_75_description/meshes/link1.STL" />
            </geometry>
        </collision>
    </link>
    <joint name="left_joint1" type="revolute">
        <origin rpy="-1.5708 0 0" xyz="0 0 0.2405" />
        <parent link="left_base_link" />
        <child link="left_Link1" />
        <axis xyz="0 -1 0" />
        <limit effort="60" lower="-3.1" upper="3.1" velocity="3.14" />
        <dynamics damping="50" friction="1" />
    </joint>
    <link name="left_Link2">
        <inertial>
            <origin rpy="0 0 0" xyz="2.72859133252335E-07 0.011077753037361 0.0761295106490881" />
            <mass value="0.432849770310974" />
            <inertia ixx="0.00125838173873093" ixy="5.63146579602116E-09" ixz="1.33486683063366E-09" iyy="0.00122245448121472" iyz="0.000279003475762058" izz="0.000317474184276672" />
        </inertial>
        <visual>
            <origin rpy="0 0 0" xyz="0 0 0" />
            <geometry>
                <mesh filename="package://rm_75_description/meshes/link2.STL" />
            </geometry>
            <material name="">
                <color rgba="1 1 1 1" />
            </material>
        </visual>
        <collision>
            <origin rpy="0 0 0" xyz="0 0 0" />
            <geometry>
                <mesh filename="package://rm_75_description/meshes/link2.STL" />
            </geometry>
        </collision>
    </link>
    <joint name="left_joint2" type="revolute">
        <origin rpy="1.5708 0 0" xyz="0 0 0" />
        <parent link="left_Link1" />
        <child link="left_Link2" />
        <axis xyz="0 1 0" />
        <limit effort="60" lower="-2.268" upper="2.268" velocity="3.14" />
        <dynamics damping="50" friction="1" />
    </joint>
    <link name="left_Link3">
        <inertial>
            <origin rpy="0 0 0" xyz="6.84676164566044E-07 0.0273475408308154 -0.0235440119707943" />
            <mass value="0.431325495678459" />
            <inertia ixx="0.000794332771462568" ixy="1.03353218375171E-08" ixz="-2.32798826854953E-09" iyy="0.000315065343266245" iyz="-0.000142620540462618" izz="0.000730371131605455" />
        </inertial>
        <visual>
            <origin rpy="0 0 0" xyz="0 0 0" />
            <geometry>
                <mesh filename="package://rm_75_description/meshes/link3.STL" />
            </geometry>
            <material name="">
                <color rgba="1 1 1 1" />
            </material>
        </visual>
        <collision>
            <origin rpy="0 0 0" xyz="0 0 0" />
            <geometry>
                <mesh filename="package://rm_75_description/meshes/link3.STL" />
            </geometry>
        </collision>
    </link>
    <joint name="left_joint3" type="revolute">
        <origin rpy="-1.5708 0 0" xyz="0 0 0.256" />
        <parent link="left_Link2" />
        <child link="left_Link3" />
        <axis xyz="0 -1 0" />
        <limit effort="30" lower="-3.1" upper="3.1" velocity="3.92" />
        <dynamics damping="50" friction="1" />
    </joint>
    <link name="left_Link4">
        <inertial>
            <origin rpy="0 0 0" xyz="5.05312670298932E-06 0.0105690692118619 0.0595925663703773" />
            <mass value="0.289633681619295" />
            <inertia ixx="0.000637371004484591" ixy="-3.86643270900744E-08" ixz="7.05261290886955E-08" iyy="0.000614178164759844" iyz="0.000144610359942128" izz="0.000156483880946498" />
        </inertial>
        <visual>
            <origin rpy="0 0 0" xyz="0 0 0" />
            <geometry>
                <mesh filename="package://rm_75_description/meshes/link4.STL" />
            </geometry>
            <material name="">
                <color rgba="1 1 1 1" />
            </material>
        </visual>
        <collision>
            <origin rpy="0 0 0" xyz="0 0 0" />
            <geometry>
                <mesh filename="package://rm_75_description/meshes/link4.STL" />
            </geometry>
        </collision>
    </link>
    <joint name="left_joint4" type="revolute">
        <origin rpy="1.5708 0 0" xyz="0 0 0" />
        <parent link="left_Link3" />
        <child link="left_Link4" />
        <axis xyz="0 1 0" />
        <limit effort="30" lower="-2.355" upper="2.355" velocity="3.92" />
        <dynamics damping="50" friction="1" />
    </joint>
    <link name="left_Link5">
        <inertial>
            <origin rpy="0 0 0" xyz="1.1551661767744E-06 0.0215394748352686 -0.0180424468598241" />
            <mass value="0.239419768320061" />
            <inertia ixx="0.000285938919722783" ixy="2.21994116852616E-09" ixz="3.07101358617598E-09" iyy="0.00011988808279186" iyz="-4.4236583260078E-05" izz="0.000262727540304212" />
        </inertial>
        <visual>
            <origin rpy="0 0 0" xyz="0 0 0" />
            <geometry>
                <mesh filename="package://rm_75_description/meshes/link5.STL" />
            </geometry>
            <material name="">
                <color rgba="1 1 1 1" />
            </material>
        </visual>
        <collision>
            <origin rpy="0 0 0" xyz="0 0 0" />
            <geometry>
                <mesh filename="package://rm_75_description/meshes/link5.STL" />
            </geometry>
        </collision>
    </link>
    <joint name="left_joint5" type="revolute">
        <origin rpy="-1.5708 0 0" xyz="0 0 0.21" />
        <parent link="left_Link4" />
        <child link="left_Link5" />
        <axis xyz="0 -1 0" />
        <limit effort="10" lower="-3.1" upper="3.1" velocity="3.92" />
        <dynamics damping="50" friction="1" />
    </joint>
    <link name="left_Link6">
        <inertial>
            <origin rpy="0 0 0" xyz="3.19794787018954E-06 0.00736804250989373 0.0593808368101291" />
            <mass value="0.218799761431682" />
            <inertia ixx="0.000350540363914436" ixy="-1.7705645712277E-08" ixz="3.41781620449632E-08" iyy="0.000334482418423991" iyz="7.82431228462317E-05" izz="0.000104927867487584" />
        </inertial>
        <visual>
            <origin rpy="0 0 0" xyz="0 0 0" />
            <geometry>
                <mesh filename="package://rm_75_description/meshes/link6.STL" />
            </geometry>
            <material name="">
                <color rgba="1 1 1 1" />
            </material>
        </visual>
        <collision>
            <origin rpy="0 0 0" xyz="0 0 0" />
            <geometry>
                <mesh filename="package://rm_75_description/meshes/link6.STL" />
            </geometry>
        </collision>
    </link>
    <joint name="left_joint6" type="revolute">
        <origin rpy="1.5708 0 0" xyz="0 0 0" />
        <parent link="left_Link5" />
        <child link="left_Link6" />
        <axis xyz="0 1 0" />
        <limit effort="10" lower="-2.233" upper="2.233" velocity="3.92" />
        <dynamics damping="50" friction="1" />
    </joint>
    <link name="left_Link7">
        <inertial>
            <origin rpy="0 0 0" xyz="0.000714238382876259 -0.000396711987952758 -0.0126723660946126" />
            <mass value="0.0649018034311231" />
            <inertia ixx="2.02766547502765E-05" ixy="-1.32505200276848E-06" ixz="-2.58450915224912E-08" iyy="1.87986725225022E-05" iyz="3.39471452123283E-09" izz="3.17885459163081E-05" />
        </inertial>
        <visual>
            <origin rpy="0 0 0" xyz="0 0 0" />
            <geometry>
                <mesh filename="package://rm_75_description/meshes/link7.STL" />
            </geometry>
            <material name="">
                <color rgba="1 1 1 1" />
            </material>
        </visual>
        <collision>
            <origin rpy="0 0 0" xyz="0 0 0" />
            <geometry>
                <mesh filename="package://rm_75_description/meshes/link7.STL" />
            </geometry>
        </collision>
    </link>
    <joint name="left_joint7" type="revolute">
        <origin rpy="0 0 0" xyz="0 0 0.144" />
        <parent link="left_Link6" />
        <child link="left_Link7" />
        <axis xyz="0 0 1" />
        <limit effort="10" lower="-6.28" upper="6.28" velocity="3.92" />
        <dynamics damping="50" friction="1" />
    </joint>
    <transmission name="tran1">
        <type>transmission_interface/SimpleTransmission</type>
        <joint name="left_joint1">
            <hardwareInterface>hardware_interface/PositionJointInterface</hardwareInterface>
        </joint>
        <actuator name="motor1">
            <hardwareInterface>hardware_interface/PositionJointInterface</hardwareInterface>
            <mechanicalReduction>1</mechanicalReduction>
        </actuator>
    </transmission>
    <transmission name="tran1">
        <type>transmission_interface/SimpleTransmission</type>
        <joint name="left_joint2">
            <hardwareInterface>hardware_interface/PositionJointInterface</hardwareInterface>
        </joint>
        <actuator name="motor1">
            <hardwareInterface>hardware_interface/PositionJointInterface</hardwareInterface>
            <mechanicalReduction>1</mechanicalReduction>
        </actuator>
    </transmission>
    <transmission name="tran1">
        <type>transmission_interface/SimpleTransmission</type>
        <joint name="left_joint3">
            <hardwareInterface>hardware_interface/PositionJointInterface</hardwareInterface>
        </joint>
        <actuator name="motor1">
            <hardwareInterface>hardware_interface/PositionJointInterface</hardwareInterface>
            <mechanicalReduction>1</mechanicalReduction>
        </actuator>
    </transmission>
    <transmission name="tran1">
        <type>transmission_interface/SimpleTransmission</type>
        <joint name="left_joint4">
            <hardwareInterface>hardware_interface/PositionJointInterface</hardwareInterface>
        </joint>
        <actuator name="motor1">
            <hardwareInterface>hardware_interface/PositionJointInterface</hardwareInterface>
            <mechanicalReduction>1</mechanicalReduction>
        </actuator>
    </transmission>
    <transmission name="tran1">
        <type>transmission_interface/SimpleTransmission</type>
        <joint name="left_joint5">
            <hardwareInterface>hardware_interface/PositionJointInterface</hardwareInterface>
        </joint>
        <actuator name="motor1">
            <hardwareInterface>hardware_interface/PositionJointInterface</hardwareInterface>
            <mechanicalReduction>1</mechanicalReduction>
        </actuator>
    </transmission>
    <transmission name="tran1">
        <type>transmission_interface/SimpleTransmission</type>
        <joint name="left_joint6">
            <hardwareInterface>hardware_interface/PositionJointInterface</hardwareInterface>
        </joint>
        <actuator name="motor1">
            <hardwareInterface>hardware_interface/PositionJointInterface</hardwareInterface>
            <mechanicalReduction>1</mechanicalReduction>
        </actuator>
    </transmission>
    <transmission name="tran1">
        <type>transmission_interface/SimpleTransmission</type>
        <joint name="left_joint7">
            <hardwareInterface>hardware_interface/PositionJointInterface</hardwareInterface>
        </joint>
        <actuator name="motor1">
            <hardwareInterface>hardware_interface/PositionJointInterface</hardwareInterface>
            <mechanicalReduction>1</mechanicalReduction>
        </actuator>
    </transmission>
    <joint name="L_hand_base_joint" type="fixed">
        <origin rpy="3.1415926 0 1.5" xyz="0 0 0.03" />
        <parent link="left_Link7" />
        <child link="L_flange" />
    </joint>
    <link name="L_flange">
        <visual>
            <origin rpy="0 0 0" xyz="0 0 0" />
            <geometry>
                <mesh filename="package://rm_75_description/urdf/inspire_URDF/L_inspire/meshes/flange.STL" scale="0.001 0.001 0.001" />
            </geometry>
            <material name="">
                <color rgba="1 1 1 1" />
            </material>
        </visual>
        <collision>
            <origin rpy="0 0 0" xyz="0 0 0" />
            <geometry>
                <mesh filename="package://rm_75_description/urdf/inspire_URDF/L_inspire/meshes/flange.STL" scale="0.001 0.001 0.001" />
            </geometry>
        </collision>
        <inertial>
            <origin rpy="0 0 0" xyz="0 0 0" />
            <mass value="1.0372398E-01" />
            <inertia ixx="8.6985265E-05" ixy="0" ixz="2.7728445E-07" iyy="8.7567207E-05" iyz="6.8674339E-07" izz="7.4487068E-05" />
        </inertial>
    </link>
    <joint name="L_base_link_joint" type="fixed">
        <origin rpy="1.570796 0 0" xyz="0 0 0" />
        <parent link="L_flange" />
        <child link="L_hand_base_link" />
    </joint>
    <link name="L_hand_base_link">
        <inertial>
            <origin rpy="0 0 0" xyz="-0.002551 -0.066047 -0.0019357" />
            <mass value="0.14143" />
            <inertia ixx="0.0001234" ixy="2.1995E-06" ixz="-1.7694E-06" iyy="8.3835E-05" iyz="1.5968E-06" izz="7.7231E-05" />
        </inertial>
        <visual>
            <origin rpy="0 0 0" xyz="0 0 0" />
            <geometry>
                <mesh filename="package://rm_75_description/urdf/inspire_URDF/L_inspire/meshes/base_link.STL" />
            </geometry>
            <material name="">
                <color rgba="1 1 1 1" />
            </material>
        </visual>
        <collision>
            <origin rpy="0 0 0" xyz="0 0 0" />
            <geometry>
                <mesh filename="package://rm_75_description/urdf/inspire_URDF/L_inspire/meshes/base_link.STL" />
            </geometry>
        </collision>
    </link>
    <link name="L_thumb_proximal_base">
        <inertial>
            <origin rpy="0 0 0" xyz="0.0048817 0.00038782 -0.00722" />
            <mass value="0.0018869" />
            <inertia ixx="5.5158E-08" ixy="-1.1803E-08" ixz="-4.6743E-09" iyy="8.2164E-08" iyz="-1.3521E-09" izz="6.7434E-08" />
        </inertial>
        <visual>
            <origin rpy="0 0 0" xyz="0 0 0" />
            <geometry>
                <mesh filename="package://rm_75_description/urdf/inspire_URDF/L_inspire/meshes/Link11.STL" />
            </geometry>
            <material name="">
                <color rgba="0.82745 0.83922 0.82745 1" />
            </material>
        </visual>
        <collision>
            <origin rpy="0 0 0" xyz="0 0 0" />
            <geometry>
                <mesh filename="package://rm_75_description/urdf/inspire_URDF/L_inspire/meshes/Link11.STL" />
            </geometry>
        </collision>
    </link>
    <joint name="L_thumb_proximal_yaw_joint" type="revolute">
        <origin rpy="1.5708 -1.5708 0" xyz="-0.01696 -0.0691 0.02045" />
        <parent link="L_hand_base_link" />
        <child link="L_thumb_proximal_base" />
        <axis xyz="0 0 1" />
        <limit effort="1" lower="-0.1" upper="1.3" velocity="0.5" />
    </joint>
    <link name="L_thumb_proximal">
        <inertial>
            <origin rpy="0 0 0" xyz="0.021936 -0.01279 -0.0080386" />
            <mass value="0.0066101" />
            <inertia ixx="1.5693E-06" ixy="7.8339E-07" ixz="8.5959E-10" iyy="1.7356E-06" iyz="1.0378E-09" izz="2.787E-06" />
        </inertial>
        <visual>
            <origin rpy="0 0 0" xyz="0 0 0" />
            <geometry>
                <mesh filename="package://rm_75_description/urdf/inspire_URDF/L_inspire/meshes/Link12.STL" />
            </geometry>
            <material name="">
                <color rgba="1 1 1 1" />
            </material>
        </visual>
        <collision>
            <origin rpy="0 0 0" xyz="0 0 0" />
            <geometry>
                <mesh filename="package://rm_75_description/urdf/inspire_URDF/L_inspire/meshes/Link12.STL" />
            </geometry>
        </collision>
    </link>
    <joint name="L_thumb_proximal_pitch_joint" type="revolute">
        <origin rpy="-1.5708 0 0.16939" xyz="0.0099867 0.0098242 -0.0089" />
        <parent link="L_thumb_proximal_base" />
        <child link="L_thumb_proximal" />
        <axis xyz="0 0 -1" />
        <limit effort="1" lower="-0.1" upper="0.6" velocity="0.5" />
    </joint>
    <link name="L_thumb_intermediate">
        <inertial>
            <origin rpy="0 0 0" xyz="0.0095531 0.0016282 -0.0072002" />
            <mass value="0.0037844" />
            <inertia ixx="3.6981E-07" ixy="9.8603E-08" ixz="-2.8173E-12" iyy="3.2395E-07" iyz="-2.8028E-12" izz="4.6532E-07" />
        </inertial>
        <visual>
            <origin rpy="0 0 0" xyz="0 0 0" />
            <geometry>
                <mesh filename="package://rm_75_description/urdf/inspire_URDF/L_inspire/meshes/Link13.STL" />
            </geometry>
            <material name="">
                <color rgba="1 1 1 1" />
            </material>
        </visual>
        <collision>
            <origin rpy="0 0 0" xyz="0 0 0" />
            <geometry>
                <mesh filename="package://rm_75_description/urdf/inspire_URDF/L_inspire/meshes/Link13.STL" />
            </geometry>
        </collision>
    </link>
    <joint name="L_thumb_intermediate_joint" type="revolute">
        <origin rpy="0 0 0" xyz="0.04407 -0.034553 -0.0008" />
        <parent link="L_thumb_proximal" />
        <child link="L_thumb_intermediate" />
        <axis xyz="0 0 -1" />
        <limit effort="1" lower="0" upper="0.8" velocity="0.5" />
        <mimic joint="L_thumb_proximal_pitch_joint" multiplier="1.6" offset="0" />
    </joint>
    <link name="L_thumb_distal">
        <inertial>
            <origin rpy="0 0 0" xyz="0.0092888 -0.004953 -0.0060033" />
            <mass value="0.003344" />
            <inertia ixx="1.3632E-07" ixy="5.6787E-08" ixz="-9.1939E-11" iyy="1.4052E-07" iyz="1.2145E-10" izz="2.0026E-07" />
        </inertial>
        <visual>
            <origin rpy="0 0 0" xyz="0 0 0" />
            <geometry>
                <mesh filename="package://rm_75_description/urdf/inspire_URDF/L_inspire/meshes/Link14.STL" />
            </geometry>
            <material name="">
                <color rgba="1 1 1 1" />
            </material>
        </visual>
        <collision>
            <origin rpy="0 0 0" xyz="0 0 0" />
            <geometry>
                <mesh filename="package://rm_75_description/urdf/inspire_URDF/L_inspire/meshes/Link14.STL" />
            </geometry>
        </collision>
    </link>
    <joint name="L_thumb_distal_joint" type="revolute">
        <origin rpy="0 0 0" xyz="0.020248 -0.010156 -0.0012" />
        <parent link="L_thumb_intermediate" />
        <child link="L_thumb_distal" />
        <axis xyz="0 0 -1" />
        <limit effort="1" lower="0" upper="1.2" velocity="0.5" />
        <mimic joint="L_thumb_proximal_pitch_joint" multiplier="2.4" offset="0" />
    </joint>
    <link name="L_index_proximal">
        <inertial>
            <origin rpy="0 0 0" xyz="0.0012971 -0.011934 -0.0059998" />
            <mass value="0.0042405" />
            <inertia ixx="6.6215E-07" ixy="1.8442E-08" ixz="1.3746E-12" iyy="2.1167E-07" iyz="-1.4773E-11" izz="6.9402E-07" />
        </inertial>
        <visual>
            <origin rpy="0 0 0" xyz="0 0 0" />
            <geometry>
                <mesh filename="package://rm_75_description/urdf/inspire_URDF/L_inspire/meshes/Link15.STL" />
            </geometry>
            <material name="">
                <color rgba="0.79216 0.81961 0.93333 1" />
            </material>
        </visual>
        <collision>
            <origin rpy="0 0 0" xyz="0 0 0" />
            <geometry>
                <mesh filename="package://rm_75_description/urdf/inspire_URDF/L_inspire/meshes/Link15.STL" />
            </geometry>
        </collision>
    </link>
    <joint name="L_index_proximal_joint" type="revolute">
        <origin rpy="-0.034907 0 0" xyz="0.00028533 -0.13653 0.032268" />
        <parent link="L_hand_base_link" />
        <child link="L_index_proximal" />
        <axis xyz="0 0 -1" />
        <limit effort="1" lower="0" upper="1.7" velocity="0.5" />
    </joint>
    <link name="L_index_intermediate">
        <inertial>
            <origin rpy="0 0 0" xyz="0.0021753 -0.019567 -0.005" />
            <mass value="0.0045682" />
            <inertia ixx="7.6284E-07" ixy="-8.063E-08" ixz="3.6797E-13" iyy="9.4308E-08" iyz="1.5743E-13" izz="7.8176E-07" />
        </inertial>
        <visual>
            <origin rpy="0 0 0" xyz="0 0 0" />
            <geometry>
                <mesh filename="package://rm_75_description/urdf/inspire_URDF/L_inspire/meshes/Link16.STL" />
            </geometry>
            <material name="">
                <color rgba="1 1 1 1" />
            </material>
        </visual>
        <collision>
            <origin rpy="0 0 0" xyz="0 0 0" />
            <geometry>
                <mesh filename="package://rm_75_description/urdf/inspire_URDF/L_inspire/meshes/Link16.STL" />
            </geometry>
        </collision>
    </link>
    <joint name="L_index_intermediate_joint" type="revolute">
        <origin rpy="0 0 0" xyz="-0.0024229 -0.032041 -0.001" />
        <parent link="L_index_proximal" />
        <child link="L_index_intermediate" />
        <axis xyz="0 0 -1" />
        <limit effort="1" lower="0" upper="1.7" velocity="0.5" />
        <mimic joint="L_index_proximal_joint" multiplier="1" offset="0" />
    </joint>
    <link name="L_middle_proximal">
        <inertial>
            <origin rpy="0 0 0" xyz="0.0012971 -0.011934 -0.0059999" />
            <mass value="0.0042405" />
            <inertia ixx="6.6215E-07" ixy="1.8442E-08" ixz="1.2299E-12" iyy="2.1167E-07" iyz="-1.4484E-11" izz="6.9402E-07" />
        </inertial>
        <visual>
            <origin rpy="0 0 0" xyz="0 0 0" />
            <geometry>
                <mesh filename="package://rm_75_description/urdf/inspire_URDF/L_inspire/meshes/Link17.STL" />
            </geometry>
            <material name="">
                <color rgba="0.79216 0.81961 0.93333 1" />
            </material>
        </visual>
        <collision>
            <origin rpy="0 0 0" xyz="0 0 0" />
            <geometry>
                <mesh filename="package://rm_75_description/urdf/inspire_URDF/L_inspire/meshes/Link17.STL" />
            </geometry>
        </collision>
    </link>
    <joint name="L_middle_proximal_joint" type="revolute">
        <origin rpy="0 0 0" xyz="0.00028533 -0.1371 0.01295" />
        <parent link="L_hand_base_link" />
        <child link="L_middle_proximal" />
        <axis xyz="0 0 -1" />
        <limit effort="1" lower="0" upper="1.7" velocity="0.5" />
    </joint>
    <link name="L_middle_intermediate">
        <inertial>
            <origin rpy="0 0 0" xyz="0.001921 -0.020796 -0.0049999" />
            <mass value="0.0050397" />
            <inertia ixx="9.5823E-07" ixy="-1.1425E-07" ixz="-2.4186E-12" iyy="1.0646E-07" iyz="3.6974E-12" izz="9.8385E-07" />
        </inertial>
        <visual>
            <origin rpy="0 0 0" xyz="0 0 0" />
            <geometry>
                <mesh filename="package://rm_75_description/urdf/inspire_URDF/L_inspire/meshes/Link18.STL" />
            </geometry>
            <material name="">
                <color rgba="0.82745 0.83922 0.82745 1" />
            </material>
        </visual>
        <collision>
            <origin rpy="0 0 0" xyz="0 0 0" />
            <geometry>
                <mesh filename="package://rm_75_description/urdf/inspire_URDF/L_inspire/meshes/Link18.STL" />
            </geometry>
        </collision>
    </link>
    <joint name="L_middle_intermediate_joint" type="revolute">
        <origin rpy="0 0 0" xyz="-0.0024229 -0.032041 -0.001" />
        <parent link="L_middle_proximal" />
        <child link="L_middle_intermediate" />
        <axis xyz="0 0 -1" />
        <limit effort="1" lower="0" upper="1.7" velocity="0.5" />
        <mimic joint="L_middle_proximal_joint" multiplier="1" offset="0" />
    </joint>
    <link name="L_ring_proximal">
        <inertial>
            <origin rpy="0 0 0" xyz="0.0012971 -0.011934 -0.0059999" />
            <mass value="0.0042405" />
            <inertia ixx="6.6215E-07" ixy="1.8442E-08" ixz="9.6052E-13" iyy="2.1167E-07" iyz="-1.4124E-11" izz="6.9402E-07" />
        </inertial>
        <visual>
            <origin rpy="0 0 0" xyz="0 0 0" />
            <geometry>
                <mesh filename="package://rm_75_description/urdf/inspire_URDF/L_inspire/meshes/Link19.STL" />
            </geometry>
            <material name="">
                <color rgba="0.79216 0.81961 0.93333 1" />
            </material>
        </visual>
        <collision>
            <origin rpy="0 0 0" xyz="0 0 0" />
            <geometry>
                <mesh filename="package://rm_75_description/urdf/inspire_URDF/L_inspire/meshes/Link19.STL" />
            </geometry>
        </collision>
    </link>
    <joint name="L_ring_proximal_joint" type="revolute">
        <origin rpy="0.05236 0 0" xyz="0.00028533 -0.13691 -0.0062872" />
        <parent link="L_hand_base_link" />
        <child link="L_ring_proximal" />
        <axis xyz="0 0 -1" />
        <limit effort="1" lower="0" upper="1.7" velocity="0.5" />
    </joint>
    <link name="L_ring_intermediate">
        <inertial>
            <origin rpy="0 0 0" xyz="0.0021753 -0.019567 -0.005" />
            <mass value="0.0045682" />
            <inertia ixx="7.6285E-07" ixy="-8.0631E-08" ixz="3.3472E-14" iyy="9.4308E-08" iyz="-4.4773E-13" izz="7.8176E-07" />
        </inertial>
        <visual>
            <origin rpy="0 0 0" xyz="0 0 0" />
            <geometry>
                <mesh filename="package://rm_75_description/urdf/inspire_URDF/L_inspire/meshes/Link20.STL" />
            </geometry>
            <material name="">
                <color rgba="1 1 1 1" />
            </material>
        </visual>
        <collision>
            <origin rpy="0 0 0" xyz="0 0 0" />
            <geometry>
                <mesh filename="package://rm_75_description/urdf/inspire_URDF/L_inspire/meshes/Link20.STL" />
            </geometry>
        </collision>
    </link>
    <joint name="L_ring_intermediate_joint" type="revolute">
        <origin rpy="0 0 0" xyz="-0.0024229 -0.032041 -0.001" />
        <parent link="L_ring_proximal" />
        <child link="L_ring_intermediate" />
        <axis xyz="0 0 -1" />
        <limit effort="1" lower="0" upper="1.7" velocity="0.5" />
        <mimic joint="L_ring_proximal_joint" multiplier="1" offset="0" />
    </joint>
    <link name="L_pinky_proximal">
        <inertial>
            <origin rpy="0 0 0" xyz="0.0012971 -0.011934 -0.0059999" />
            <mass value="0.0042405" />
            <inertia ixx="6.6215E-07" ixy="1.8442E-08" ixz="1.0279E-12" iyy="2.1167E-07" iyz="-1.4277E-11" izz="6.9402E-07" />
        </inertial>
        <visual>
            <origin rpy="0 0 0" xyz="0 0 0" />
            <geometry>
                <mesh filename="package://rm_75_description/urdf/inspire_URDF/L_inspire/meshes/Link21.STL" />
            </geometry>
            <material name="">
                <color rgba="0.79216 0.81961 0.93333 1" />
            </material>
        </visual>
        <collision>
            <origin rpy="0 0 0" xyz="0 0 0" />
            <geometry>
                <mesh filename="package://rm_75_description/urdf/inspire_URDF/L_inspire/meshes/Link21.STL" />
            </geometry>
        </collision>
    </link>
    <joint name="L_pinky_proximal_joint" type="revolute">
        <origin rpy="0.10472 0 0" xyz="0.00028533 -0.13571 -0.025488" />
        <parent link="L_hand_base_link" />
        <child link="L_pinky_proximal" />
        <axis xyz="0 0 -1" />
        <limit effort="1" lower="0" upper="1.7" velocity="0.5" />
    </joint>
    <link name="L_pinky_intermediate">
        <inertial>
            <origin rpy="0 0 0" xyz="0.0024788 -0.016208 -0.0050001" />
            <mass value="0.0036036" />
            <inertia ixx="4.3923E-07" ixy="-4.1355E-08" ixz="1.2263E-12" iyy="7.0315E-08" iyz="3.1311E-12" izz="4.4881E-07" />
        </inertial>
        <visual>
            <origin rpy="0 0 0" xyz="0 0 0" />
            <geometry>
                <mesh filename="package://rm_75_description/urdf/inspire_URDF/L_inspire/meshes/Link22.STL" />
            </geometry>
            <material name="">
                <color rgba="1 1 1 1" />
            </material>
        </visual>
        <collision>
            <origin rpy="0 0 0" xyz="0 0 0" />
            <geometry>
                <mesh filename="package://rm_75_description/urdf/inspire_URDF/L_inspire/meshes/Link22.STL" />
            </geometry>
        </collision>
    </link>
    <joint name="L_pinky_intermediate_joint" type="revolute">
        <origin rpy="0 0 0" xyz="-0.0024229 -0.032041 -0.001" />
        <parent link="L_pinky_proximal" />
        <child link="L_pinky_intermediate" />
        <axis xyz="0 0 -1" />
        <limit effort="1" lower="0" upper="1.7" velocity="0.5" />
        <mimic joint="L_pinky_proximal_joint" multiplier="1" offset="0" />
    </joint>
    <joint name="right_dummy_joint" type="fixed">
        <origin rpy="0 0 0" xyz="0 -0.3 0" />
        <parent link="dummy" />
        <child link="right_base_link" />
    </joint>
    <!-- ///////////////////////////////////////   bottom_joint   ////////////////////////////////////////// -->
    <joint name="right_bottom_joint" type="fixed">
        <origin rpy="0 0 0" xyz="0 0 0" />
        <parent link="right_base_link" />
        <child link="right_bottom_link" />
    </joint>
    <link name="right_bottom_link">
        <visual>
            <origin rpy="0 0 0" xyz=" 0 0 -0.02" />
            <geometry>
                <box size="0.06 0.06 0.02" />
            </geometry>
            <material name="Brown" />
        </visual>
        <collision>
            <origin rpy="0 0 0" xyz=" 0 0 -0.02" />
            <geometry>
                <box size="0.06 0.06 0.02" />
            </geometry>
        </collision>
        <inertial>
            <mass value="500" />
            <inertia ixx="41.68333333333333" ixy="0" ixz="0" iyy="83.33333333333333" iyz="0" izz="41.68333333333333" />
            <origin xyz="0 0 0" rpy="0 0 0" />
        </inertial>
    </link>
    <link name="right_base_link">
        <inertial>
            <origin rpy="0 0 0" xyz="0.000433268851866144 3.54527840972405E-05 0.0599427623574736" />
            <mass value="0.841071174772543" />
            <inertia ixx="0.00172611149818605" ixy="2.52724703312125E-06" ixz="3.67689528877993E-05" iyy="0.00170987425756066" iyz="-1.68009023667311E-06" izz="0.000904023916742301" />
        </inertial>
        <visual>
            <origin rpy="0 0 0" xyz="0 0 0" />
            <geometry>
                <mesh filename="package://rm_75_description/meshes/base_link.STL" />
            </geometry>
            <material name="">
                <color rgba="1 1 1 1" />
            </material>
        </visual>
        <collision>
            <origin rpy="0 0 0" xyz="0 0 0" />
            <geometry>
                <mesh filename="package://rm_75_description/meshes/base_link.STL" />
            </geometry>
        </collision>
    </link>
    <link name="right_Link1">
        <inertial>
            <origin rpy="0 0 0" xyz="0.0251854224372461 1.19160585601655E-08 -0.021107996993288" />
            <mass value="0.593563458735581" />
            <inertia ixx="0.000561352422092522" ixy="9.8019294192418E-09" ixz="-0.000211217278563478" iyy="0.00126614121202124" iyz="1.29510293158304E-08" izz="0.0011816817861243" />
        </inertial>
        <visual>
            <origin rpy="0 0 0" xyz="0 0 0" />
            <geometry>
                <mesh filename="package://rm_75_description/meshes/link1.STL" />
            </geometry>
            <material name="">
                <color rgba="1 1 1 1" />
            </material>
        </visual>
        <collision>
            <origin rpy="0 0 0" xyz="0 0 0" />
            <geometry>
                <mesh filename="package://rm_75_description/meshes/link1.STL" />
            </geometry>
        </collision>
    </link>
    <joint name="right_joint1" type="revolute">
        <origin rpy="-1.5708 0 0" xyz="0 0 0.2405" />
        <parent link="right_base_link" />
        <child link="right_Link1" />
        <axis xyz="0 -1 0" />
        <limit effort="60" lower="-3.1" upper="3.1" velocity="3.14" />
        <dynamics damping="50" friction="1" />
    </joint>
    <link name="right_Link2">
        <inertial>
            <origin rpy="0 0 0" xyz="2.72859133252335E-07 0.011077753037361 0.0761295106490881" />
            <mass value="0.432849770310974" />
            <inertia ixx="0.00125838173873093" ixy="5.63146579602116E-09" ixz="1.33486683063366E-09" iyy="0.00122245448121472" iyz="0.000279003475762058" izz="0.000317474184276672" />
        </inertial>
        <visual>
            <origin rpy="0 0 0" xyz="0 0 0" />
            <geometry>
                <mesh filename="package://rm_75_description/meshes/link2.STL" />
            </geometry>
            <material name="">
                <color rgba="1 1 1 1" />
            </material>
        </visual>
        <collision>
            <origin rpy="0 0 0" xyz="0 0 0" />
            <geometry>
                <mesh filename="package://rm_75_description/meshes/link2.STL" />
            </geometry>
        </collision>
    </link>
    <joint name="right_joint2" type="revolute">
        <origin rpy="1.5708 0 0" xyz="0 0 0" />
        <parent link="right_Link1" />
        <child link="right_Link2" />
        <axis xyz="0 1 0" />
        <limit effort="60" lower="-2.268" upper="2.268" velocity="3.14" />
        <dynamics damping="50" friction="1" />
    </joint>
    <link name="right_Link3">
        <inertial>
            <origin rpy="0 0 0" xyz="6.84676164566044E-07 0.0273475408308154 -0.0235440119707943" />
            <mass value="0.431325495678459" />
            <inertia ixx="0.000794332771462568" ixy="1.03353218375171E-08" ixz="-2.32798826854953E-09" iyy="0.000315065343266245" iyz="-0.000142620540462618" izz="0.000730371131605455" />
        </inertial>
        <visual>
            <origin rpy="0 0 0" xyz="0 0 0" />
            <geometry>
                <mesh filename="package://rm_75_description/meshes/link3.STL" />
            </geometry>
            <material name="">
                <color rgba="1 1 1 1" />
            </material>
        </visual>
        <collision>
            <origin rpy="0 0 0" xyz="0 0 0" />
            <geometry>
                <mesh filename="package://rm_75_description/meshes/link3.STL" />
            </geometry>
        </collision>
    </link>
    <joint name="right_joint3" type="revolute">
        <origin rpy="-1.5708 0 0" xyz="0 0 0.256" />
        <parent link="right_Link2" />
        <child link="right_Link3" />
        <axis xyz="0 -1 0" />
        <limit effort="30" lower="-3.1" upper="3.1" velocity="3.92" />
        <dynamics damping="50" friction="1" />
    </joint>
    <link name="right_Link4">
        <inertial>
            <origin rpy="0 0 0" xyz="5.05312670298932E-06 0.0105690692118619 0.0595925663703773" />
            <mass value="0.289633681619295" />
            <inertia ixx="0.000637371004484591" ixy="-3.86643270900744E-08" ixz="7.05261290886955E-08" iyy="0.000614178164759844" iyz="0.000144610359942128" izz="0.000156483880946498" />
        </inertial>
        <visual>
            <origin rpy="0 0 0" xyz="0 0 0" />
            <geometry>
                <mesh filename="package://rm_75_description/meshes/link4.STL" />
            </geometry>
            <material name="">
                <color rgba="1 1 1 1" />
            </material>
        </visual>
        <collision>
            <origin rpy="0 0 0" xyz="0 0 0" />
            <geometry>
                <mesh filename="package://rm_75_description/meshes/link4.STL" />
            </geometry>
        </collision>
    </link>
    <joint name="right_joint4" type="revolute">
        <origin rpy="1.5708 0 0" xyz="0 0 0" />
        <parent link="right_Link3" />
        <child link="right_Link4" />
        <axis xyz="0 1 0" />
        <limit effort="30" lower="-2.355" upper="2.355" velocity="3.92" />
        <dynamics damping="50" friction="1" />
    </joint>
    <link name="right_Link5">
        <inertial>
            <origin rpy="0 0 0" xyz="1.1551661767744E-06 0.0215394748352686 -0.0180424468598241" />
            <mass value="0.239419768320061" />
            <inertia ixx="0.000285938919722783" ixy="2.21994116852616E-09" ixz="3.07101358617598E-09" iyy="0.00011988808279186" iyz="-4.4236583260078E-05" izz="0.000262727540304212" />
        </inertial>
        <visual>
            <origin rpy="0 0 0" xyz="0 0 0" />
            <geometry>
                <mesh filename="package://rm_75_description/meshes/link5.STL" />
            </geometry>
            <material name="">
                <color rgba="1 1 1 1" />
            </material>
        </visual>
        <collision>
            <origin rpy="0 0 0" xyz="0 0 0" />
            <geometry>
                <mesh filename="package://rm_75_description/meshes/link5.STL" />
            </geometry>
        </collision>
    </link>
    <joint name="right_joint5" type="revolute">
        <origin rpy="-1.5708 0 0" xyz="0 0 0.21" />
        <parent link="right_Link4" />
        <child link="right_Link5" />
        <axis xyz="0 -1 0" />
        <limit effort="10" lower="-3.1" upper="3.1" velocity="3.92" />
        <dynamics damping="50" friction="1" />
    </joint>
    <link name="right_Link6">
        <inertial>
            <origin rpy="0 0 0" xyz="3.19794787018954E-06 0.00736804250989373 0.0593808368101291" />
            <mass value="0.218799761431682" />
            <inertia ixx="0.000350540363914436" ixy="-1.7705645712277E-08" ixz="3.41781620449632E-08" iyy="0.000334482418423991" iyz="7.82431228462317E-05" izz="0.000104927867487584" />
        </inertial>
        <visual>
            <origin rpy="0 0 0" xyz="0 0 0" />
            <geometry>
                <mesh filename="package://rm_75_description/meshes/link6.STL" />
            </geometry>
            <material name="">
                <color rgba="1 1 1 1" />
            </material>
        </visual>
        <collision>
            <origin rpy="0 0 0" xyz="0 0 0" />
            <geometry>
                <mesh filename="package://rm_75_description/meshes/link6.STL" />
            </geometry>
        </collision>
    </link>
    <joint name="right_joint6" type="revolute">
        <origin rpy="1.5708 0 0" xyz="0 0 0" />
        <parent link="right_Link5" />
        <child link="right_Link6" />
        <axis xyz="0 1 0" />
        <limit effort="10" lower="-2.233" upper="2.233" velocity="3.92" />
        <dynamics damping="50" friction="1" />
    </joint>
    <link name="right_Link7">
        <inertial>
            <origin rpy="0 0 0" xyz="0.000714238382876259 -0.000396711987952758 -0.0126723660946126" />
            <mass value="0.0649018034311231" />
            <inertia ixx="2.02766547502765E-05" ixy="-1.32505200276848E-06" ixz="-2.58450915224912E-08" iyy="1.87986725225022E-05" iyz="3.39471452123283E-09" izz="3.17885459163081E-05" />
        </inertial>
        <visual>
            <origin rpy="0 0 0" xyz="0 0 0" />
            <geometry>
                <mesh filename="package://rm_75_description/meshes/link7.STL" />
            </geometry>
            <material name="">
                <color rgba="1 1 1 1" />
            </material>
        </visual>
        <collision>
            <origin rpy="0 0 0" xyz="0 0 0" />
            <geometry>
                <mesh filename="package://rm_75_description/meshes/link7.STL" />
            </geometry>
        </collision>
    </link>
    <joint name="right_joint7" type="revolute">
        <origin rpy="0 0 0" xyz="0 0 0.144" />
        <parent link="right_Link6" />
        <child link="right_Link7" />
        <axis xyz="0 0 1" />
        <limit effort="10" lower="-6.28" upper="6.28" velocity="3.92" />
        <dynamics damping="50" friction="1" />
    </joint>
    <transmission name="tran1">
        <type>transmission_interface/SimpleTransmission</type>
        <joint name="right_joint1">
            <hardwareInterface>hardware_interface/PositionJointInterface</hardwareInterface>
        </joint>
        <actuator name="motor1">
            <hardwareInterface>hardware_interface/PositionJointInterface</hardwareInterface>
            <mechanicalReduction>1</mechanicalReduction>
        </actuator>
    </transmission>
    <transmission name="tran1">
        <type>transmission_interface/SimpleTransmission</type>
        <joint name="right_joint2">
            <hardwareInterface>hardware_interface/PositionJointInterface</hardwareInterface>
        </joint>
        <actuator name="motor1">
            <hardwareInterface>hardware_interface/PositionJointInterface</hardwareInterface>
            <mechanicalReduction>1</mechanicalReduction>
        </actuator>
    </transmission>
    <transmission name="tran1">
        <type>transmission_interface/SimpleTransmission</type>
        <joint name="right_joint3">
            <hardwareInterface>hardware_interface/PositionJointInterface</hardwareInterface>
        </joint>
        <actuator name="motor1">
            <hardwareInterface>hardware_interface/PositionJointInterface</hardwareInterface>
            <mechanicalReduction>1</mechanicalReduction>
        </actuator>
    </transmission>
    <transmission name="tran1">
        <type>transmission_interface/SimpleTransmission</type>
        <joint name="right_joint4">
            <hardwareInterface>hardware_interface/PositionJointInterface</hardwareInterface>
        </joint>
        <actuator name="motor1">
            <hardwareInterface>hardware_interface/PositionJointInterface</hardwareInterface>
            <mechanicalReduction>1</mechanicalReduction>
        </actuator>
    </transmission>
    <transmission name="tran1">
        <type>transmission_interface/SimpleTransmission</type>
        <joint name="right_joint5">
            <hardwareInterface>hardware_interface/PositionJointInterface</hardwareInterface>
        </joint>
        <actuator name="motor1">
            <hardwareInterface>hardware_interface/PositionJointInterface</hardwareInterface>
            <mechanicalReduction>1</mechanicalReduction>
        </actuator>
    </transmission>
    <transmission name="tran1">
        <type>transmission_interface/SimpleTransmission</type>
        <joint name="right_joint6">
            <hardwareInterface>hardware_interface/PositionJointInterface</hardwareInterface>
        </joint>
        <actuator name="motor1">
            <hardwareInterface>hardware_interface/PositionJointInterface</hardwareInterface>
            <mechanicalReduction>1</mechanicalReduction>
        </actuator>
    </transmission>
    <transmission name="tran1">
        <type>transmission_interface/SimpleTransmission</type>
        <joint name="right_joint7">
            <hardwareInterface>hardware_interface/PositionJointInterface</hardwareInterface>
        </joint>
        <actuator name="motor1">
            <hardwareInterface>hardware_interface/PositionJointInterface</hardwareInterface>
            <mechanicalReduction>1</mechanicalReduction>
        </actuator>
    </transmission>
    <joint name="R_hand_base_joint" type="fixed">
        <origin rpy="3.1415926 0 1.5" xyz="0 0 0.03" />
        <parent link="right_Link7" />
        <child link="R_flange" />
    </joint>
    <link name="R_flange">
        <visual>
            <origin rpy="0 0 0" xyz="0 0 0" />
            <geometry>
                <mesh filename="package://rm_75_description/urdf/inspire_URDF/R_inspire/meshes/flange.STL" scale="0.001 0.001 0.001" />
            </geometry>
            <material name="">
                <color rgba="1 1 1 1" />
            </material>
        </visual>
        <collision>
            <origin rpy="0 0 0" xyz="0 0 0" />
            <geometry>
                <mesh filename="package://rm_75_description/urdf/inspire_URDF/R_inspire/meshes/flange.STL" scale="0.001 0.001 0.001" />
            </geometry>
        </collision>
        <inertial>
            <origin rpy="0 0 0" xyz="0 0 0" />
            <mass value="1.0372398E-01" />
            <inertia ixx="8.6985265E-05" ixy="0" ixz="2.7728445E-07" iyy="8.7567207E-05" iyz="6.8674339E-07" izz="7.4487068E-05" />
        </inertial>
    </link>
    <joint name="R_base_link_joint" type="fixed">
        <origin rpy="1.570796 0 0" xyz="0 0 0" />
        <parent link="R_flange" />
        <child link="R_hand_base_link" />
    </joint>
    <link name="R_hand_base_link">
        <inertial>
            <origin rpy="0 0 0" xyz="-0.0025264 -0.066047 0.0019598" />
            <mass value="0.14143" />
            <inertia ixx="0.00012281" ixy="2.1711E-06" ixz="1.7709E-06" iyy="8.3832E-05" iyz="-1.6551E-06" izz="7.6663E-05" />
        </inertial>
        <visual>
            <origin rpy="0 0 0" xyz="0 0 0" />
            <geometry>
                <mesh filename="package://rm_75_description/urdf/inspire_URDF/R_inspire/meshes/base_link.STL" />
            </geometry>
            <material name="">
                <color rgba="1 1 1 1" />
            </material>
        </visual>
        <collision>
            <origin rpy="0 0 0" xyz="0 0 0" />
            <geometry>
                <mesh filename="package://rm_75_description/urdf/inspire_URDF/R_inspire/meshes/base_link.STL" />
            </geometry>
        </collision>
    </link>
    <link name="R_thumb_proximal_base">
        <inertial>
            <origin rpy="0 0 0" xyz="-0.0048064 0.0009382 -0.00757" />
            <mass value="0.0018869" />
            <inertia ixx="5.816E-08" ixy="1.4539E-08" ixz="4.491E-09" iyy="7.9161E-08" iyz="-1.8727E-09" izz="6.7433E-08" />
        </inertial>
        <visual>
            <origin rpy="0 0 0" xyz="0 0 0" />
            <geometry>
                <mesh filename="package://rm_75_description/urdf/inspire_URDF/R_inspire/meshes/Link11.STL" />
            </geometry>
            <material name="">
                <color rgba="1 1 1 1" />
            </material>
        </visual>
        <collision>
            <origin rpy="0 0 0" xyz="0 0 0" />
            <geometry>
                <mesh filename="package://rm_75_description/urdf/inspire_URDF/R_inspire/meshes/Link11.STL" />
            </geometry>
        </collision>
    </link>
    <joint name="R_thumb_proximal_yaw_joint" type="revolute">
        <origin rpy="1.5708 -1.5708 0" xyz="-0.01696 -0.0691 -0.02045" />
        <parent link="R_hand_base_link" />
        <child link="R_thumb_proximal_base" />
        <axis xyz="0 0 -1" />
        <limit effort="1" lower="-0.1" upper="1.3" velocity="0.5" />
    </joint>
    <link name="R_thumb_proximal">
        <inertial>
            <origin rpy="0 0 0" xyz="0.021932 0.012785 -0.0080386" />
            <mass value="0.0066075" />
            <inertia ixx="1.5686E-06" ixy="-7.8296E-07" ixz="8.9143E-10" iyy="1.7353E-06" iyz="-1.0191E-09" izz="2.786E-06" />
        </inertial>
        <visual>
            <origin rpy="0 0 0" xyz="0 0 0" />
            <geometry>
                <mesh filename="package://rm_75_description/urdf/inspire_URDF/R_inspire/meshes/Link12.STL" />
            </geometry>
            <material name="">
                <color rgba="1 1 1 1" />
            </material>
        </visual>
        <collision>
            <origin rpy="0 0 0" xyz="0 0 0" />
            <geometry>
                <mesh filename="package://rm_75_description/urdf/inspire_URDF/R_inspire/meshes/Link12.STL" />
            </geometry>
        </collision>
    </link>
    <joint name="R_thumb_proximal_pitch_joint" type="revolute">
        <origin rpy="1.5708 0 2.8587" xyz="-0.0088099 0.010892 -0.00925" />
        <parent link="R_thumb_proximal_base" />
        <child link="R_thumb_proximal" />
        <axis xyz="0 0 1" />
        <limit effort="1" lower="-0.1" upper="0.6" velocity="0.5" />
    </joint>
    <link name="R_thumb_intermediate">
        <inertial>
            <origin rpy="0 0 0" xyz="0.0095544 -0.0016282 -0.0071997" />
            <mass value="0.0037847" />
            <inertia ixx="3.6981E-07" ixy="-9.8581E-08" ixz="-4.7469E-12" iyy="3.2394E-07" iyz="1.0939E-12" izz="4.6531E-07" />
        </inertial>
        <visual>
            <origin rpy="0 0 0" xyz="0 0 0" />
            <geometry>
                <mesh filename="package://rm_75_description/urdf/inspire_URDF/R_inspire/meshes/Link13.STL" />
            </geometry>
            <material name="">
                <color rgba="1 1 1 1" />
            </material>
        </visual>
        <collision>
            <origin rpy="0 0 0" xyz="0 0 0" />
            <geometry>
                <mesh filename="package://rm_75_description/urdf/inspire_URDF/R_inspire/meshes/Link13.STL" />
            </geometry>
        </collision>
    </link>
    <joint name="R_thumb_intermediate_joint" type="revolute">
        <origin rpy="0 0 0" xyz="0.04407 0.034553 -0.0008" />
        <parent link="R_thumb_proximal" />
        <child link="R_thumb_intermediate" />
        <axis xyz="0 0 1" />
        <limit effort="1" lower="0" upper="0.8" velocity="0.5" />
        <mimic joint="R_thumb_proximal_pitch_joint" multiplier="1.6" offset="0" />
    </joint>
    <link name="R_thumb_distal">
        <inertial>
            <origin rpy="0 0 0" xyz="0.0092888 0.0049529 -0.0060033" />
            <mass value="0.0033441" />
            <inertia ixx="1.3632E-07" ixy="-5.6788E-08" ixz="-9.2764E-11" iyy="1.4052E-07" iyz="-1.2283E-10" izz="2.0026E-07" />
        </inertial>
        <visual>
            <origin rpy="0 0 0" xyz="0 0 0" />
            <geometry>
                <mesh filename="package://rm_75_description/urdf/inspire_URDF/R_inspire/meshes/Link14.STL" />
            </geometry>
            <material name="">
                <color rgba="1 1 1 1" />
            </material>
        </visual>
        <collision>
            <origin rpy="0 0 0" xyz="0 0 0" />
            <geometry>
                <mesh filename="package://rm_75_description/urdf/inspire_URDF/R_inspire/meshes/Link14.STL" />
            </geometry>
        </collision>
    </link>
    <joint name="R_thumb_distal_joint" type="revolute">
        <origin rpy="0 0 0" xyz="0.020248 0.010156 -0.0012" />
        <parent link="R_thumb_intermediate" />
        <child link="R_thumb_distal" />
        <axis xyz="0 0 1" />
        <limit effort="1" lower="0" upper="1.2" velocity="0.5" />
        <mimic joint="R_thumb_proximal_pitch_joint" multiplier="2.4" offset="0" />
    </joint>
    <link name="R_index_proximal">
        <inertial>
            <origin rpy="0 0 0" xyz="0.0012259 0.011942 -0.0060001" />
            <mass value="0.0042403" />
            <inertia ixx="6.6232E-07" ixy="-1.5775E-08" ixz="1.8515E-12" iyy="2.1146E-07" iyz="-5.0828E-12" izz="6.9398E-07" />
        </inertial>
        <visual>
            <origin rpy="0 0 0" xyz="0 0 0" />
            <geometry>
                <mesh filename="package://rm_75_description/urdf/inspire_URDF/R_inspire/meshes/Link15.STL" />
            </geometry>
            <material name="">
                <color rgba="1 1 1 1" />
            </material>
        </visual>
        <collision>
            <origin rpy="0 0 0" xyz="0 0 0" />
            <geometry>
                <mesh filename="package://rm_75_description/urdf/inspire_URDF/R_inspire/meshes/Link15.STL" />
            </geometry>
        </collision>
    </link>
    <joint name="R_index_proximal_joint" type="revolute">
        <origin rpy="-3.1067 0 0" xyz="0.00028533 -0.13653 -0.032268" />
        <parent link="R_hand_base_link" />
        <child link="R_index_proximal" />
        <axis xyz="0 0 1" />
        <limit effort="1" lower="0" upper="1.7" velocity="0.5" />
    </joint>
    <link name="R_index_intermediate">
        <inertial>
            <origin rpy="0 0 0" xyz="0.0019697 0.019589 -0.005" />
            <mass value="0.0045683" />
            <inertia ixx="7.6111E-07" ixy="8.7637E-08" ixz="-3.7751E-13" iyy="9.6076E-08" iyz="9.9444E-13" izz="7.8179E-07" />
        </inertial>
        <visual>
            <origin rpy="0 0 0" xyz="0 0 0" />
            <geometry>
                <mesh filename="package://rm_75_description/urdf/inspire_URDF/R_inspire/meshes/Link16.STL" />
            </geometry>
            <material name="">
                <color rgba="1 1 1 1" />
            </material>
        </visual>
        <collision>
            <origin rpy="0 0 0" xyz="0 0 0" />
            <geometry>
                <mesh filename="package://rm_75_description/urdf/inspire_URDF/R_inspire/meshes/Link16.STL" />
            </geometry>
        </collision>
    </link>
    <joint name="R_index_intermediate_joint" type="revolute">
        <origin rpy="0 0 0" xyz="-0.0026138 0.032026 -0.001" />
        <parent link="R_index_proximal" />
        <child link="R_index_intermediate" />
        <axis xyz="0 0 1" />
        <limit effort="1" lower="0" upper="1.7" velocity="0.5" />
        <mimic joint="R_index_proximal_joint" multiplier="1" offset="0" />
    </joint>
    <link name="R_middle_proximal">
        <inertial>
            <origin rpy="0 0 0" xyz="0.001297 0.011934 -0.0060001" />
            <mass value="0.0042403" />
            <inertia ixx="6.6211E-07" ixy="-1.8461E-08" ixz="1.8002E-12" iyy="2.1167E-07" iyz="-6.6808E-12" izz="6.9397E-07" />
        </inertial>
        <visual>
            <origin rpy="0 0 0" xyz="0 0 0" />
            <geometry>
                <mesh filename="package://rm_75_description/urdf/inspire_URDF/R_inspire/meshes/Link17.STL" />
            </geometry>
            <material name="">
                <color rgba="1 1 1 1" />
            </material>
        </visual>
        <collision>
            <origin rpy="0 0 0" xyz="0 0 0" />
            <geometry>
                <mesh filename="package://rm_75_description/urdf/inspire_URDF/R_inspire/meshes/Link17.STL" />
            </geometry>
        </collision>
    </link>
    <joint name="R_middle_proximal_joint" type="revolute">
        <origin rpy="-3.1416 0 0" xyz="0.00028533 -0.1371 -0.01295" />
        <parent link="R_hand_base_link" />
        <child link="R_middle_proximal" />
        <axis xyz="0 0 1" />
        <limit effort="1" lower="0" upper="1.7" velocity="0.5" />
    </joint>
    <link name="R_middle_intermediate">
        <inertial>
            <origin rpy="0 0 0" xyz="0.001921 0.020796 -0.005" />
            <mass value="0.0050396" />
            <inertia ixx="9.5822E-07" ixy="1.1425E-07" ixz="-2.4791E-12" iyy="1.0646E-07" iyz="5.9173E-12" izz="9.8384E-07" />
        </inertial>
        <visual>
            <origin rpy="0 0 0" xyz="0 0 0" />
            <geometry>
                <mesh filename="package://rm_75_description/urdf/inspire_URDF/R_inspire/meshes/Link18.STL" />
            </geometry>
            <material name="">
                <color rgba="1 1 1 1" />
            </material>
        </visual>
        <collision>
            <origin rpy="0 0 0" xyz="0 0 0" />
            <geometry>
                <mesh filename="package://rm_75_description/urdf/inspire_URDF/R_inspire/meshes/Link18.STL" />
            </geometry>
        </collision>
    </link>
    <joint name="R_middle_intermediate_joint" type="revolute">
        <origin rpy="0 0 0" xyz="-0.0024229 0.032041 -0.001" />
        <parent link="R_middle_proximal" />
        <child link="R_middle_intermediate" />
        <axis xyz="0 0 1" />
        <limit effort="1" lower="0" upper="1.7" velocity="0.5" />
        <mimic joint="R_middle_proximal_joint" multiplier="1" offset="0" />
    </joint>
    <link name="R_ring_proximal">
        <inertial>
            <origin rpy="0 0 0" xyz="0.001297 0.011934 -0.0060002" />
            <mass value="0.0042403" />
            <inertia ixx="6.6211E-07" ixy="-1.8461E-08" ixz="1.5793E-12" iyy="2.1167E-07" iyz="-6.6868E-12" izz="6.9397E-07" />
        </inertial>
        <visual>
            <origin rpy="0 0 0" xyz="0 0 0" />
            <geometry>
                <mesh filename="package://rm_75_description/urdf/inspire_URDF/R_inspire/meshes/Link19.STL" />
            </geometry>
            <material name="">
                <color rgba="1 1 1 1" />
            </material>
        </visual>
        <collision>
            <origin rpy="0 0 0" xyz="0 0 0" />
            <geometry>
                <mesh filename="package://rm_75_description/urdf/inspire_URDF/R_inspire/meshes/Link19.STL" />
            </geometry>
        </collision>
    </link>
    <joint name="R_ring_proximal_joint" type="revolute">
        <origin rpy="3.0892 0 0" xyz="0.00028533 -0.13691 0.0062872" />
        <parent link="R_hand_base_link" />
        <child link="R_ring_proximal" />
        <axis xyz="0 0 1" />
        <limit effort="1" lower="0" upper="1.7" velocity="0.5" />
    </joint>
    <link name="R_ring_intermediate">
        <inertial>
            <origin rpy="0 0 0" xyz="0.0021753 0.019567 -0.005" />
            <mass value="0.0045683" />
            <inertia ixx="7.6286E-07" ixy="8.0635E-08" ixz="-6.1562E-13" iyy="9.431E-08" iyz="5.8619E-13" izz="7.8177E-07" />
        </inertial>
        <visual>
            <origin rpy="0 0 0" xyz="0 0 0" />
            <geometry>
                <mesh filename="package://rm_75_description/urdf/inspire_URDF/R_inspire/meshes/Link20.STL" />
            </geometry>
            <material name="">
                <color rgba="1 1 1 1" />
            </material>
        </visual>
        <collision>
            <origin rpy="0 0 0" xyz="0 0 0" />
            <geometry>
                <mesh filename="package://rm_75_description/urdf/inspire_URDF/R_inspire/meshes/Link20.STL" />
            </geometry>
        </collision>
    </link>
    <joint name="R_ring_intermediate_joint" type="revolute">
        <origin rpy="0 0 0" xyz="-0.0024229 0.032041 -0.001" />
        <parent link="R_ring_proximal" />
        <child link="R_ring_intermediate" />
        <axis xyz="0 0 1" />
        <limit effort="1" lower="0" upper="1.7" velocity="0.5" />
        <mimic joint="R_ring_proximal_joint" multiplier="1" offset="0" />
    </joint>
    <link name="R_pinky_proximal">
        <inertial>
            <origin rpy="0 0 0" xyz="0.001297 0.011934 -0.0060001" />
            <mass value="0.0042403" />
            <inertia ixx="6.6211E-07" ixy="-1.8461E-08" ixz="1.6907E-12" iyy="2.1167E-07" iyz="-6.9334E-12" izz="6.9397E-07" />
        </inertial>
        <visual>
            <origin rpy="0 0 0" xyz="0 0 0" />
            <geometry>
                <mesh filename="package://rm_75_description/urdf/inspire_URDF/R_inspire/meshes/Link21.STL" />
            </geometry>
            <material name="">
                <color rgba="1 1 1 1" />
            </material>
        </visual>
        <collision>
            <origin rpy="0 0 0" xyz="0 0 0" />
            <geometry>
                <mesh filename="package://rm_75_description/urdf/inspire_URDF/R_inspire/meshes/Link21.STL" />
            </geometry>
        </collision>
    </link>
    <joint name="R_pinky_proximal_joint" type="revolute">
        <origin rpy="3.0369 0 0" xyz="0.00028533 -0.13571 0.025488" />
        <parent link="R_hand_base_link" />
        <child link="R_pinky_proximal" />
        <axis xyz="0 0 1" />
        <limit effort="1" lower="0" upper="1.7" velocity="0.5" />
    </joint>
    <link name="R_pinky_intermediate">
        <inertial>
            <origin rpy="0 0 0" xyz="0.0024748 0.016203 -0.0050031" />
            <mass value="0.0035996" />
            <inertia ixx="4.3913E-07" ixy="4.1418E-08" ixz="3.7168E-11" iyy="7.0247E-08" iyz="5.8613E-11" izz="4.4867E-07" />
        </inertial>
        <visual>
            <origin rpy="0 0 0" xyz="0 0 0" />
            <geometry>
                <mesh filename="package://rm_75_description/urdf/inspire_URDF/R_inspire/meshes/Link22.STL" />
            </geometry>
            <material name="">
                <color rgba="1 1 1 1" />
            </material>
        </visual>
        <collision>
            <origin rpy="0 0 0" xyz="0 0 0" />
            <geometry>
                <mesh filename="package://rm_75_description/urdf/inspire_URDF/R_inspire/meshes/Link22.STL" />
            </geometry>
        </collision>
    </link>
    <joint name="R_pinky_intermediate_joint" type="revolute">
        <origin rpy="0 0 0" xyz="-0.0024229 0.032041 -0.001" />
        <parent link="R_pinky_proximal" />
        <child link="R_pinky_intermediate" />
        <axis xyz="0 0 1" />
        <limit effort="1" lower="0" upper="1.7" velocity="0.5" />
        <mimic joint="R_pinky_proximal_joint" multiplier="1" offset="0" />
    </joint>
    <!-- ros_control plugin -->
    <gazebo>
        <plugin filename="libgazebo_ros_control.so" name="gazebo_ros_control">
            <robotNamespace>/arm</robotNamespace>
            <robotSimType>gazebo_ros_control/DefaultRobotHWSim</robotSimType>
            <legacyModeNS>true</legacyModeNS>
        </plugin>
    </gazebo>
    <transmission name="trans_L_thumb_proximal_yaw_joint">
        <type>transmission_interface/SimpleTransmission</type>
        <joint name="L_thumb_proximal_yaw_joint">
            <hardwareInterface>hardware_interface/EffortJointInterface</hardwareInterface>
        </joint>
        <actuator name="L_thumb_proximal_yaw_joint_motor">
            <hardwareInterface>hardware_interface/EffortJointInterface</hardwareInterface>
            <mechanicalReduction>1</mechanicalReduction>
        </actuator>
    </transmission>
    <transmission name="trans_L_thumb_proximal_pitch_joint">
        <type>transmission_interface/SimpleTransmission</type>
        <joint name="L_thumb_proximal_pitch_joint">
            <hardwareInterface>hardware_interface/EffortJointInterface</hardwareInterface>
        </joint>
        <actuator name="L_thumb_proximal_pitch_joint_motor">
            <hardwareInterface>hardware_interface/EffortJointInterface</hardwareInterface>
            <mechanicalReduction>1</mechanicalReduction>
        </actuator>
    </transmission>
    <transmission name="trans_L_thumb_intermediate_joint">
        <type>transmission_interface/SimpleTransmission</type>
        <joint name="L_thumb_intermediate_joint">
            <hardwareInterface>hardware_interface/EffortJointInterface</hardwareInterface>
        </joint>
        <actuator name="L_thumb_intermediate_joint_motor">
            <hardwareInterface>hardware_interface/EffortJointInterface</hardwareInterface>
            <mechanicalReduction>1</mechanicalReduction>
        </actuator>
    </transmission>
    <transmission name="trans_L_thumb_distal_joint">
        <type>transmission_interface/SimpleTransmission</type>
        <joint name="L_thumb_distal_joint">
            <hardwareInterface>hardware_interface/EffortJointInterface</hardwareInterface>
        </joint>
        <actuator name="L_thumb_distal_joint_motor">
            <hardwareInterface>hardware_interface/EffortJointInterface</hardwareInterface>
            <mechanicalReduction>1</mechanicalReduction>
        </actuator>
    </transmission>
    <transmission name="trans_L_index_proximal_joint">
        <type>transmission_interface/SimpleTransmission</type>
        <joint name="L_index_proximal_joint">
            <hardwareInterface>hardware_interface/EffortJointInterface</hardwareInterface>
        </joint>
        <actuator name="L_index_proximal_joint_motor">
            <hardwareInterface>hardware_interface/EffortJointInterface</hardwareInterface>
            <mechanicalReduction>1</mechanicalReduction>
        </actuator>
    </transmission>
    <transmission name="trans_L_index_intermediate_joint">
        <type>transmission_interface/SimpleTransmission</type>
        <joint name="L_index_intermediate_joint">
            <hardwareInterface>hardware_interface/EffortJointInterface</hardwareInterface>
        </joint>
        <actuator name="L_index_intermediate_joint_motor">
            <hardwareInterface>hardware_interface/EffortJointInterface</hardwareInterface>
            <mechanicalReduction>1</mechanicalReduction>
        </actuator>
    </transmission>
    <transmission name="trans_L_middle_proximal_joint">
        <type>transmission_interface/SimpleTransmission</type>
        <joint name="L_middle_proximal_joint">
            <hardwareInterface>hardware_interface/EffortJointInterface</hardwareInterface>
        </joint>
        <actuator name="L_middle_proximal_joint_motor">
            <hardwareInterface>hardware_interface/EffortJointInterface</hardwareInterface>
            <mechanicalReduction>1</mechanicalReduction>
        </actuator>
    </transmission>
    <transmission name="trans_L_middle_intermediate_joint">
        <type>transmission_interface/SimpleTransmission</type>
        <joint name="L_middle_intermediate_joint">
            <hardwareInterface>hardware_interface/EffortJointInterface</hardwareInterface>
        </joint>
        <actuator name="L_middle_intermediate_joint_motor">
            <hardwareInterface>hardware_interface/EffortJointInterface</hardwareInterface>
            <mechanicalReduction>1</mechanicalReduction>
        </actuator>
    </transmission>
    <transmission name="trans_L_ring_proximal_joint">
        <type>transmission_interface/SimpleTransmission</type>
        <joint name="L_ring_proximal_joint">
            <hardwareInterface>hardware_interface/EffortJointInterface</hardwareInterface>
        </joint>
        <actuator name="L_ring_proximal_joint_motor">
            <hardwareInterface>hardware_interface/EffortJointInterface</hardwareInterface>
            <mechanicalReduction>1</mechanicalReduction>
        </actuator>
    </transmission>
    <transmission name="trans_L_ring_intermediate_joint">
        <type>transmission_interface/SimpleTransmission</type>
        <joint name="L_ring_intermediate_joint">
            <hardwareInterface>hardware_interface/EffortJointInterface</hardwareInterface>
        </joint>
        <actuator name="L_ring_intermediate_joint_motor">
            <hardwareInterface>hardware_interface/EffortJointInterface</hardwareInterface>
            <mechanicalReduction>1</mechanicalReduction>
        </actuator>
    </transmission>
    <transmission name="trans_L_pinky_proximal_joint">
        <type>transmission_interface/SimpleTransmission</type>
        <joint name="L_pinky_proximal_joint">
            <hardwareInterface>hardware_interface/EffortJointInterface</hardwareInterface>
        </joint>
        <actuator name="L_pinky_proximal_joint_motor">
            <hardwareInterface>hardware_interface/EffortJointInterface</hardwareInterface>
            <mechanicalReduction>1</mechanicalReduction>
        </actuator>
    </transmission>
    <transmission name="trans_L_pinky_intermediate_joint">
        <type>transmission_interface/SimpleTransmission</type>
        <joint name="L_pinky_intermediate_joint">
            <hardwareInterface>hardware_interface/EffortJointInterface</hardwareInterface>
        </joint>
        <actuator name="L_pinky_intermediate_joint_motor">
            <hardwareInterface>hardware_interface/EffortJointInterface</hardwareInterface>
            <mechanicalReduction>1</mechanicalReduction>
        </actuator>
    </transmission>
    <transmission name="trans_R_thumb_proximal_yaw_joint">
        <type>transmission_interface/SimpleTransmission</type>
        <joint name="R_thumb_proximal_yaw_joint">
            <hardwareInterface>hardware_interface/EffortJointInterface</hardwareInterface>
        </joint>
        <actuator name="R_thumb_proximal_yaw_joint_motor">
            <hardwareInterface>hardware_interface/EffortJointInterface</hardwareInterface>
            <mechanicalReduction>1</mechanicalReduction>
        </actuator>
    </transmission>
    <transmission name="trans_R_thumb_proximal_pitch_joint">
        <type>transmission_interface/SimpleTransmission</type>
        <joint name="R_thumb_proximal_pitch_joint">
            <hardwareInterface>hardware_interface/EffortJointInterface</hardwareInterface>
        </joint>
        <actuator name="R_thumb_proximal_pitch_joint_motor">
            <hardwareInterface>hardware_interface/EffortJointInterface</hardwareInterface>
            <mechanicalReduction>1</mechanicalReduction>
        </actuator>
    </transmission>
    <transmission name="trans_R_thumb_intermediate_joint">
        <type>transmission_interface/SimpleTransmission</type>
        <joint name="R_thumb_intermediate_joint">
            <hardwareInterface>hardware_interface/EffortJointInterface</hardwareInterface>
        </joint>
        <actuator name="R_thumb_intermediate_joint_motor">
            <hardwareInterface>hardware_interface/EffortJointInterface</hardwareInterface>
            <mechanicalReduction>1</mechanicalReduction>
        </actuator>
    </transmission>
    <transmission name="trans_R_thumb_distal_joint">
        <type>transmission_interface/SimpleTransmission</type>
        <joint name="R_thumb_distal_joint">
            <hardwareInterface>hardware_interface/EffortJointInterface</hardwareInterface>
        </joint>
        <actuator name="R_thumb_distal_joint_motor">
            <hardwareInterface>hardware_interface/EffortJointInterface</hardwareInterface>
            <mechanicalReduction>1</mechanicalReduction>
        </actuator>
    </transmission>
    <transmission name="trans_R_index_proximal_joint">
        <type>transmission_interface/SimpleTransmission</type>
        <joint name="R_index_proximal_joint">
            <hardwareInterface>hardware_interface/EffortJointInterface</hardwareInterface>
        </joint>
        <actuator name="R_index_proximal_joint_motor">
            <hardwareInterface>hardware_interface/EffortJointInterface</hardwareInterface>
            <mechanicalReduction>1</mechanicalReduction>
        </actuator>
    </transmission>
    <transmission name="trans_R_index_intermediate_joint">
        <type>transmission_interface/SimpleTransmission</type>
        <joint name="R_index_intermediate_joint">
            <hardwareInterface>hardware_interface/EffortJointInterface</hardwareInterface>
        </joint>
        <actuator name="R_index_intermediate_joint_motor">
            <hardwareInterface>hardware_interface/EffortJointInterface</hardwareInterface>
            <mechanicalReduction>1</mechanicalReduction>
        </actuator>
    </transmission>
    <transmission name="trans_R_middle_proximal_joint">
        <type>transmission_interface/SimpleTransmission</type>
        <joint name="R_middle_proximal_joint">
            <hardwareInterface>hardware_interface/EffortJointInterface</hardwareInterface>
        </joint>
        <actuator name="R_middle_proximal_joint_motor">
            <hardwareInterface>hardware_interface/EffortJointInterface</hardwareInterface>
            <mechanicalReduction>1</mechanicalReduction>
        </actuator>
    </transmission>
    <transmission name="trans_R_middle_intermediate_joint">
        <type>transmission_interface/SimpleTransmission</type>
        <joint name="R_middle_intermediate_joint">
            <hardwareInterface>hardware_interface/EffortJointInterface</hardwareInterface>
        </joint>
        <actuator name="R_middle_intermediate_joint_motor">
            <hardwareInterface>hardware_interface/EffortJointInterface</hardwareInterface>
            <mechanicalReduction>1</mechanicalReduction>
        </actuator>
    </transmission>
    <transmission name="trans_R_ring_proximal_joint">
        <type>transmission_interface/SimpleTransmission</type>
        <joint name="R_ring_proximal_joint">
            <hardwareInterface>hardware_interface/EffortJointInterface</hardwareInterface>
        </joint>
        <actuator name="R_ring_proximal_joint_motor">
            <hardwareInterface>hardware_interface/EffortJointInterface</hardwareInterface>
            <mechanicalReduction>1</mechanicalReduction>
        </actuator>
    </transmission>
    <transmission name="trans_R_ring_intermediate_joint">
        <type>transmission_interface/SimpleTransmission</type>
        <joint name="R_ring_intermediate_joint">
            <hardwareInterface>hardware_interface/EffortJointInterface</hardwareInterface>
        </joint>
        <actuator name="R_ring_intermediate_joint_motor">
            <hardwareInterface>hardware_interface/EffortJointInterface</hardwareInterface>
            <mechanicalReduction>1</mechanicalReduction>
        </actuator>
    </transmission>
    <transmission name="trans_R_pinky_proximal_joint">
        <type>transmission_interface/SimpleTransmission</type>
        <joint name="R_pinky_proximal_joint">
            <hardwareInterface>hardware_interface/EffortJointInterface</hardwareInterface>
        </joint>
        <actuator name="R_pinky_proximal_joint_motor">
            <hardwareInterface>hardware_interface/EffortJointInterface</hardwareInterface>
            <mechanicalReduction>1</mechanicalReduction>
        </actuator>
    </transmission>
    <transmission name="trans_R_pinky_intermediate_joint">
        <type>transmission_interface/SimpleTransmission</type>
        <joint name="R_pinky_intermediate_joint">
            <hardwareInterface>hardware_interface/EffortJointInterface</hardwareInterface>
        </joint>
        <actuator name="R_pinky_intermediate_joint_motor">
            <hardwareInterface>hardware_interface/EffortJointInterface</hardwareInterface>
            <mechanicalReduction>1</mechanicalReduction>
        </actuator>
    </transmission>
</robot>

